Workbook

Sheet Explanation
A1: =Languages!A3 -> Payroll inventarisatie document | N1: =Languages!A2 -> Voorkeurstaal document:
P2: Nederlands
A3: =Languages!A4 -> De gegevens in dit Excel-document zullen worden gebruikt voor de inrichting van het HRM- en salarissysteem (Cobra)
A4: =Languages!A5 -> Het is belangrijk dat alle tabbladen worden ingevuld. Als een veld niet van toepassing is, geef dat dan aan met NVT
A5: =Languages!A6 -> Als het niet helemaal duidelijk is wat er moet worden ingevuld, neem dan contact op met uw contactpersoon binnen SDWorx
A6: =Languages!A7 -> Onderaan elke pagina is een opmerkingen veld opgenomen voor aanvullende informatie en uitleg
A8: =Tabel3[[#This Row],[Value based on users choice]] -> Indien dit document niet volledig is ingevuld kunnen we helaas niet starten met de (payroll) inrichting
A9: =Tabel3[[#This Row],[Value based on users choice]] -> omdat aanpassingen in een later stadium complex zijn om door te voeren en onnodige vertragingen veroorzaken
A11: =Languages!A10 -> Opstart documenten
A12: =Languages!A11 -> Voor de juiste opstart van de payroll hebben wij ook de volgende documenten nodig:
A13: =Languages!A12 -> Kopie beschikking WHK premie lopend jaar
A14: =Languages!A13 -> Kopie historisch overzicht vorig jaar
A15: =Languages!A14 -> Kopie loonstroken (van de laatste maand, in ieder geval een “standaard” maand)
A16: =Languages!A15 -> Kopie van de overige output van de laatste reguliere salarisadministratie
A17: =Languages!A16 -> Kopie pensioenregeling (indien van toepassing)
A18: =Languages!A17 -> Kopie WIA (excedent)regeling (indien van toepassing) (en/of andere regelingen)
A19: =Languages!A18 -> Kopie van het grootboekschema, laatste journaalpost (rapport en importbestand)
A20: =Languages!A19 -> Salarisschalen indien van toepassing
A21: =Languages!A20 -> Organogram (indien beschikbaar)?
A22: =Languages!A21 -> De vijf meest complexe loonstroken
... A24: =Languages!A23 -> Indien van toepassing de regeling individueel keuzebudget (IKB).
A25: =Languages!A66 -> Overzicht van de functiecodes en omschrijvingen (lang en kort)
A27: =Languages!A24 -> OPMERKING:
A28: =Languages!A25 -> Indien de organisatie uit meerdere BV's (betaalgroepen) bestaat, gelieve dan voor elke BV een inventarisatiedocument in te vullen.
A29: =Languages!A26 -> Indien de bedrijfsregelingen identiek zijn, dan kunt u dit aangeven bij de opmerkingen.

Sheet General Company Info
A1: =Languages!A27 -> Algemene bedrijfsgegevens
A3: =Languages!A28 -> Bedrijf | I3: =Languages!A45 -> Bank gegevens
A4: =Languages!A29 -> Naam | I4: =Languages!A46 -> SEPA betaalbestand t.b.v. nettolonen
A5: =Languages!A30 -> Adres | I5: =Languages!A47 -> IBAN-rekeningnummer
A6: =Languages!A31 -> Nummer | I6: =Languages!A48 -> Naam bank
A7: =Languages!A32 -> Postcode | I7: =Languages!A49 -> BIC code
A8: =Languages!A33 -> Plaats | I8: =Languages!A50 -> Alleen als de bank niet in de IBAN zone zit
A10: =Languages!A34 -> Contactpersoon | I10: =Languages!A51 -> Bedrijfsinstellingen
A11: =Languages!A29 -> Naam | I11: =Languages!A52 -> Collectieve arbeidsovk (CAO)
A12: =Languages!A35 -> Afdeling | I12: =Languages!A53 -> Uren per jaar
A13: =Languages!A36 -> Telefoon | I13: =Languages!A54 -> Uren per week
A14: =Languages!A37 -> E-mail | I14: =Languages!A55 -> Uren per dag | M14: =Languages!A56 -> ma: | O14: =Languages!A57 -> di: | Q14: =Languages!A58 -> wo: | S14: =Languages!A59 -> do: | U14: =Languages!A60 -> vr:
A16: =Languages!A38 -> Bedrijf details
A17: =Languages!A39 -> Bedrijf is een aparte juridische entiteit
A18: =Languages!A40 -> Bedrijf is een BV onder een juridische entiteit
A19: =Languages!A41 -> zo ja, onder welke
A25: =Languages!A42 -> Opmerkingen:
A26: IBAN nog niet bekend, kan dit later worden doorgegeven?
A29: Explanation tabblad > Regel 13, 16, 17

Sheet Payroll settings
A1: =Languages!A69 -> Salaris instellingen
A3: =Languages!A69 -> Salaris instellingen | I3: =Languages!A200 -> Uurloonberekening
A4: =Languages!A70 -> Prorata berekening gebasseerd op | I4: =Languages!A201 -> Looncodes die meetellen | M4: NVT
A5: =Languages!A71 -> Salaris periode | I5: =Languages!A202 -> voor de uurloonberekening
A7: =Languages!A72 -> Salarisstrook
A8: =Languages!A73 -> Voorkeurstaal
A9: =Languages!A74 -> Logo op salarisstrook
A10: =Languages!A75 -> Extra cumulatieven op salarisstrook | I10: =Languages!A81 -> 30% regeling
A11: =Languages!A76 -> indien ja, welke | I11: =Languages!A82 -> 30% regeling van toepassing | M11: Nee
I12: =Languages!A83 -> Aflaging in de berekening
I14: =Languages!A84 -> Overige medewerker typen
A15: =Languages!A77 -> Salarisstrook zichtbaar voor mdw | I15: =Languages!A85 -> Stagiaire | M15: Nee
A16: =Languages!A78 -> # dagen na de betaaldatum | I16: =Languages!A86 -> Oproepkracht | M16: Nee
I17: =Languages!A196 -> Split payroll | M17: Nee
A18: =Languages!A79 -> Kostenplaats | I18: =Languages!A197 -> Expats | M18: Nee
A19: =Languages!A80 -> Is afdelingscode gelijk aan kostenplaatscode? | F19: Ja | I19: =Languages!A198 -> Uitkeringsgerechtigen | M19: Nee
I20: =Languages!A199 -> Gepensioneerde | M20: Nee
I22: =Languages!A87 -> Periodiek uitbetalen van reserveringen voor oproepkrachten
I23: =Languages!A88 -> Vakantiegeld | M23: Nee | P23: =Languages!A195 -> welk %
I24: =Languages!A89 -> Vakantiedagen | M24: Nee | P24: =Languages!A195 -> welk %
A25: =Languages!A42 -> Opmerkingen:
A26: Volledige kopie admin van DO-IT Organic B.V. qua regelingen en instellingen

Sheet Payroll tax data
A1: =Languages!A90 -> Loonbelasting gegevens
A3: =Languages!A136 -> Loonbelasting
A4: =Languages!A91 -> Loonheffingsnummer
A5: =Languages!A92 -> Bedrijfsnaam
A6: =Languages!A194 -> Loontijdvak
A8: =Languages!A34 -> Contactpersoon
A9: =Languages!A36 -> Telefoon
A10: =Languages!A93 -> E-mail
A12: =Languages!A94 -> Sector
A13: =Languages!A95 -> Indeling werkgever
A15: Whk
A16: =Languages!A97 -> Eigen risicodrager
A17: =Languages!A98 -> WGA premie (totaal)
A18: =Languages!A99 -> Verhaal op de werknemer
A19: =Languages!A100 -> ZW premie
A21: =Languages!A101 -> Overige info
A22: =Languages!A102 -> CBS CAO code
A23: =Languages!A203 -> WBSO subsidie
A25: =Languages!A42 -> Opmerkingen:

Sheet Accruals
A1: =Languages!A103 -> Reserveringen
A3: =Languages!A88 -> Vakantiegeld | J3: =Languages!A116 -> 13e maand
A4: =Languages!A104 -> Referentie jaar | E4: =Languages!A61 -> van: | F4: Juni | G4: =Languages!A62 -> tot: | H4: Mei | J4: =Languages!A104 -> Referentie jaar | N4: =Languages!A61 -> van: | P4: =Languages!A62 -> tot:
A5: =Languages!A105 -> Uitbetalingspercentage | J5: =Languages!A105 -> Uitbetalingspercentage
A6: =Languages!A106 -> Periodiek reserveren | J6: =Languages!A106 -> Periodiek reserveren
A7: =Languages!A107 -> Sociale lasten reserveren | J7: =Languages!A107 -> Sociale lasten reserveren
A8: =Languages!A108 -> zo ja, welk pecentage? | J8: =Languages!A108 -> zo ja, welk pecentage?
A10: =Languages!A109 -> Betaling gebasseerd op | J10: =Languages!A109 -> Betaling gebasseerd op
A11: =Languages!A110 -> Indien peilmaand, wat is de peilmaand? | J11: =Languages!A110 -> Indien peilmaand, wat is de peilmaand?
A13: =Languages!A111 -> Welke looncodes tellen in de | E13: =Languages!A65 -> Graag opgeven op tabblad "Wage codes" | J13: =Languages!A111 -> Welke looncodes tellen in de | N13: =Languages!A65 -> Graag opgeven op tabblad "Wage codes"
A14: =Languages!A112 -> grondslag | J14: =Languages!A112 -> grondslag
A16: =Languages!A113 -> Uitbetaling in periode/maand | J16: =Languages!A113 -> Uitbetaling in periode/maand
A17: =Languages!A114 -> Uitbetaling in aparte run | J17: =Languages!A114 -> Uitbetaling in aparte run
A19: =Languages!A115 -> Minimum per periode/maand | E19: 0 | J19: =Languages!A115 -> Minimum per periode/maand
A21: =Languages!A204 -> Uitbetalen in periode/maand uitdienst | E21: Ja | J21: =Languages!A204 -> Uitbetalen in periode/maand uitdienst
A25: =Languages!A42 -> Opmerkingen:
A26: Enkel vakantiegeld invullen

Sheet Accruals (2)
A1: =Languages!A103 -> Reserveringen
A3: =Languages!A117 -> Reservering 3 | J3: =Languages!A118 -> Reservering 4
A4: =Languages!A104 -> Referentie jaar | E4: =Languages!A61 -> van: | G4: =Languages!A62 -> tot: | J4: =Languages!A104 -> Referentie jaar | N4: =Languages!A61 -> van: | P4: =Languages!A62 -> tot:
A5: =Languages!A105 -> Uitbetalingspercentage | J5: =Languages!A105 -> Uitbetalingspercentage
A6: =Languages!A106 -> Periodiek reserveren | J6: =Languages!A106 -> Periodiek reserveren
A7: =Languages!A107 -> Sociale lasten reserveren | J7: =Languages!A107 -> Sociale lasten reserveren
A8: =Languages!A108 -> zo ja, welk pecentage? | J8: =Languages!A108 -> zo ja, welk pecentage?
A10: =Languages!A109 -> Betaling gebasseerd op | J10: =Languages!A109 -> Betaling gebasseerd op
A11: =Languages!A110 -> Indien peilmaand, wat is de peilmaand? | J11: =Languages!A110 -> Indien peilmaand, wat is de peilmaand?
A13: =Languages!A111 -> Welke looncodes tellen in de | J13: =Languages!A111 -> Welke looncodes tellen in de
A14: =Languages!A112 -> grondslag | J14: =Languages!A112 -> grondslag
A18: =Languages!A113 -> Uitbetaling in periode/maand | J18: =Languages!A113 -> Uitbetaling in periode/maand
A19: =Languages!A114 -> Uitbetaling in aparte run | J19: =Languages!A114 -> Uitbetaling in aparte run
A21: =Languages!A115 -> Minimum per periode/maand | J21: =Languages!A115 -> Minimum per periode/maand
A23: =Languages!A204 -> Uitbetalen in periode/maand uitdienst | J23: =Languages!A204 -> Uitbetalen in periode/maand uitdienst
A25: =Languages!A42 -> Opmerkingen:

Sheet Accruals (IKB)
A1: =Languages!A103 -> Reserveringen
A3: =Languages!A119 -> Individueel keuze budget
A4: =Languages!A104 -> Referentie jaar | E4: =Languages!A61 -> van: | G4: =Languages!A62 -> tot:
A5: =Languages!A105 -> Uitbetalingspercentage
A6: =Languages!A106 -> Periodiek reserveren
A7: =Languages!A107 -> Sociale lasten reserveren
A8: =Languages!A108 -> zo ja, welk pecentage?
A10: =Languages!A109 -> Betaling gebasseerd op
A11: =Languages!A110 -> Indien peilmaand, wat is de peilmaand?
A13: =Languages!A111 -> Welke looncodes tellen in de
A14: =Languages!A112 -> grondslag
A18: =Languages!A113 -> Uitbetaling in periode/maand
A19: =Languages!A114 -> Uitbetaling in aparte run
A21: =Languages!A115 -> Minimum per periode/maand
A23: =Languages!A204 -> Uitbetalen in periode/maand uitdienst
A25: =Languages!A42 -> Opmerkingen:

Sheet (Pension)Scheme
A1: =Languages!A120 -> Regelingen
A3: =Languages!A121 -> Pensioen regeling
A4: =Languages!A122 -> Aangesloten bij bedrijfspensioenfonds | E4: Nee | K4: =Languages!A138 -> Basis periode
A5: =Languages!A123 -> zo ja, welke?
A6: =Languages!A124 -> Berekeningsmethode conform BPF? | K6: =Languages!A111 -> Welke looncodes tellen in de | O6: =Languages!A65 -> Graag opgeven op tabblad "Wage codes"
K7: =Languages!A139 -> (pensioen)grondslag
A8: =Languages!A125 -> Start leeftijdsbepaling
A9: =Languages!A126 -> Minimum leeftijd | E9: =Languages!A63 -> Jaren: | G9: =Languages!A64 -> Maanden:
A10: =Languages!A127 -> Begin of eind periode
A12: =Languages!A128 -> Einde leeftijdsbepaling | K12: =Languages!A140 -> Is er een leeftijdsstaffel van toepassing?
A13: =Languages!A129 -> Maximum leeftijd | E13: =Languages!A63 -> Jaren: | G13: =Languages!A64 -> Maanden: | K13: =Languages!A141 -> zo ja, graag specificeren | O13: =Languages!A143 -> Leeftijd | P13: =Languages!A144 -> % Wkn | Q13: =Languages!A145 -> % Wkg
A14: =Languages!A127 -> Begin of eind periode
A16: =Languages!A131 -> Werknemers %
A17: =Languages!A130 -> Werkgevers %
A18: =Languages!A132 -> Franchise
A19: =Languages!A133 -> Maximum jaarbedrag
A21: =Languages!A134 -> Vermenigvuldigingsfactor
A22: =Languages!A135 -> Deelfactor
A25: =Languages!A42 -> Opmerkingen:
A26: =Languages!A137 -> Als UPA aangifte van toepassing is, geef hier dan de account informatie op. Zoals gebruikersinfo, wachtwoord en productcodes.
A27: Hoeft verder niet gevuld te worden

Sheet (Pension)Scheme (2)
A1: =Languages!A120 -> Regelingen
A3: =Languages!A146 -> Pensioen excedent regeling
A4: =Languages!A122 -> Aangesloten bij bedrijfspensioenfonds | E4: Nee | K4: =Languages!A138 -> Basis periode
A5: =Languages!A123 -> zo ja, welke?
A6: =Languages!A124 -> Berekeningsmethode conform BPF? | K6: =Languages!A111 -> Welke looncodes tellen in de
K7: =Languages!A139 -> (pensioen)grondslag
A8: =Languages!A125 -> Start leeftijdsbepaling
A9: =Languages!A126 -> Minimum leeftijd | E9: =Languages!A63 -> Jaren: | G9: =Languages!A64 -> Maanden:
A10: =Languages!A127 -> Begin of eind periode
A12: =Languages!A128 -> Einde leeftijdsbepaling | K12: =Languages!A140 -> Is er een leeftijdsstaffel van toepassing?
A13: =Languages!A129 -> Maximum leeftijd | E13: =Languages!A63 -> Jaren: | G13: =Languages!A64 -> Maanden: | K13: =Languages!A141 -> zo ja, graag specificeren | O13: =Languages!A143 -> Leeftijd | P13: =Languages!A144 -> % Wkn | Q13: =Languages!A145 -> % Wkg
A14: =Languages!A127 -> Begin of eind periode
A16: =Languages!A131 -> Werknemers %
A17: =Languages!A130 -> Werkgevers %
A18: =Languages!A132 -> Franchise
A19: =Languages!A133 -> Maximum jaarbedrag
A21: =Languages!A134 -> Vermenigvuldigingsfactor
A22: =Languages!A135 -> Deelfactor
A25: =Languages!A42 -> Opmerkingen:
A26: =Languages!A137 -> Als UPA aangifte van toepassing is, geef hier dan de account informatie op. Zoals gebruikersinfo, wachtwoord en productcodes.
A27: Hoeft niet gevuld te worden

Sheet (WGA_WIA)Scheme (3)
A1: =Languages!A120 -> Regelingen
A3: =Languages!A147 -> WGA - WIA regeling
A4: =Languages!A122 -> Aangesloten bij bedrijfspensioenfonds | E4: Nee | K4: =Languages!A138 -> Basis periode
A5: =Languages!A123 -> zo ja, welke?
A6: =Languages!A124 -> Berekeningsmethode conform BPF? | K6: =Languages!A111 -> Welke looncodes tellen in de
K7: =Languages!A139 -> (pensioen)grondslag
A8: =Languages!A125 -> Start leeftijdsbepaling
A9: =Languages!A126 -> Minimum leeftijd | E9: =Languages!A63 -> Jaren: | G9: =Languages!A64 -> Maanden:
A10: =Languages!A127 -> Begin of eind periode
A12: =Languages!A128 -> Einde leeftijdsbepaling | K12: =Languages!A140 -> Is er een leeftijdsstaffel van toepassing?
A13: =Languages!A129 -> Maximum leeftijd | E13: =Languages!A63 -> Jaren: | G13: =Languages!A64 -> Maanden: | K13: =Languages!A141 -> zo ja, graag specificeren | O13: =Languages!A143 -> Leeftijd | P13: =Languages!A144 -> % Wkn | Q13: =Languages!A145 -> % Wkg
A14: =Languages!A127 -> Begin of eind periode
A16: =Languages!A131 -> Werknemers %
A17: =Languages!A130 -> Werkgevers %
A18: =Languages!A132 -> Franchise
A19: =Languages!A133 -> Maximum jaarbedrag
A21: =Languages!A134 -> Vermenigvuldigingsfactor
A22: =Languages!A135 -> Deelfactor
A25: =Languages!A42 -> Opmerkingen:
A26: =Languages!A137 -> Als UPA aangifte van toepassing is, geef hier dan de account informatie op. Zoals gebruikersinfo, wachtwoord en productcodes.
A27: Hoeft verder niet gevuld te worden

Sheet (Other)Scheme (4)
A1: =Languages!A120 -> Regelingen
A3: =Languages!A148 -> Overige regelingen
A4: =Languages!A122 -> Aangesloten bij bedrijfspensioenfonds | E4: Nee | K4: =Languages!A138 -> Basis periode
A5: =Languages!A123 -> zo ja, welke?
A6: =Languages!A124 -> Berekeningsmethode conform BPF? | K6: =Languages!A111 -> Welke looncodes tellen in de
K7: =Languages!A139 -> (pensioen)grondslag
A8: =Languages!A125 -> Start leeftijdsbepaling
A9: =Languages!A126 -> Minimum leeftijd | E9: =Languages!A63 -> Jaren: | G9: =Languages!A64 -> Maanden:
A10: =Languages!A127 -> Begin of eind periode
A12: =Languages!A128 -> Einde leeftijdsbepaling | K12: =Languages!A140 -> Is er een leeftijdsstaffel van toepassing?
A13: =Languages!A129 -> Maximum leeftijd | E13: =Languages!A63 -> Jaren: | G13: =Languages!A64 -> Maanden: | K13: =Languages!A141 -> zo ja, graag specificeren | O13: =Languages!A143 -> Leeftijd | P13: =Languages!A144 -> % Wkn | Q13: =Languages!A145 -> % Wkg
A14: =Languages!A127 -> Begin of eind periode
A16: =Languages!A131 -> Werknemers %
A17: =Languages!A130 -> Werkgevers %
A18: =Languages!A132 -> Franchise
A19: =Languages!A133 -> Maximum jaarbedrag
A21: =Languages!A134 -> Vermenigvuldigingsfactor
A22: =Languages!A135 -> Deelfactor
A25: =Languages!A42 -> Opmerkingen:
A26: =Languages!A137 -> Als UPA aangifte van toepassing is, geef hier dan de account informatie op. Zoals gebruikersinfo, wachtwoord en productcodes.
A27: Hoeft niet gevuld te worden

Sheet GL Legders & Cost centers
A1: =Languages!A149 -> Grootboekrekeningen en kostenplaatsen
A3: =Languages!A150 -> Grootboekrekening | D3: =Languages!A153 -> Kostenplaats | G3: =Languages!A154 -> Kostendrager | J3: =Languages!A155 -> Kostensoort
A4: =Languages!A151 -> Nummer | B4: =Languages!A152 -> Omschrijving | D4: =Languages!A151 -> Nummer | E4: =Languages!A152 -> Omschrijving | G4: =Languages!A151 -> Nummer | H4: =Languages!A152 -> Omschrijving | J4: =Languages!A151 -> Nummer | K4: =Languages!A152 -> Omschrijving
A5: Hoeft niet gevuld te worden

Sheet GL file export
A1: =Languages!A156 -> Journaalpost export
A3: =Languages!A157 -> Journaalpost | I3: =Languages!A174 -> Overige instellingen
A4: =Languages!A156 -> Journaalpost export | I4: =Languages!A175 -> Afwijkende rekeningschema per kpl
A5: =Languages!A158 -> Voor welk financieel systeem | I5: =Languages!A176 -> Consolideren op kostenplaats
I6: =Languages!A177 -> Consolideren op GB-rekening
A7: =Languages!A159 -> Formaat | I7: =Languages!A178 -> zo ja, specificeer
A8: =Languages!A160 -> Bestandstype
A9: =Languages!A161 -> Als anders, welk type?
A10: =Languages!A162 -> Kopregel
A11: if yes, please specify
A13: =Languages!A163 -> Detail regels
A14: =Languages!A164 -> Kolom 01
A15: =Languages!A165 -> Kolom 02
A16: =Languages!A166 -> Kolom 03
A17: =Languages!A167 -> Kolom 04
A18: =Languages!A168 -> Kolom 05
A19: =Languages!A169 -> Kolom 06
A20: =Languages!A170 -> Kolom 07
A21: =Languages!A171 -> Kolom 08
A22: =Languages!A172 -> Kolom 09
A23: =Languages!A173 -> Kolom 10
A25: =Languages!A42 -> Opmerkingen:
A26: Hoeft niet gevuld te worden

Sheet WAZO
A1: =Languages!A179 -> Wettelijke verlofregelingen
A3: =Languages!A180 -> Soort verlof | B3: =Languages!A191 -> Pensioen naar rato | D3: =Languages!A192 -> Vakakantiegeld naar rato
A4: =Languages!A181 -> Onbetaald verlof
A5: =Languages!A182 -> Kortdurend zorgverlof
A6: =Languages!A183 -> Langdurig zorgverlof
A7: =Languages!A184 -> Geboorteverlof (1 week)
A8: =Languages!A185 -> Aanvullende geboorteverlof (5 weken) | E8: =Languages!A193 -> aanvullen tot
A9: =Languages!A186 -> Betaald ouderschapsverlof | E9: =Languages!A193 -> aanvullen tot
A10: =Languages!A187 -> Onbetaald ouderschapsverlof
A12: =Languages!A188 -> Generatiepact
A13: =Languages!A189 -> Is er een generatiepact regeling?
A14: =Languages!A190 -> zo ja, wat zijn de percenages?
A25: =Languages!A42 -> Opmerkingen:
A26: Graag vullen

Sheet Wage codes
A1: SDW Wage code | B1: Existing code | C1: Description | D1: Fixed | E1: Variable | F1: Gross | G1: Nett to Gross | H1: Fiscal addition | I1: Normal Rate | J1: Special Rate | K1: Nett | L1: Input | M1: Input type | N1: Calculation method (when input type is hours/number) | O1: Earning/ Deduction | P1: Labor Cost Scheme (WKR) | Q1: Basis for pension | R1: Basis for holliday allowance | S1: Basis for 13th month | T1: Ledger accout debit | U1: Ledger account credit | V1: Remarks

Sheet Approval
A1: =Languages!A205 -> Goedkeuring setup en schaduwverwerking
A3: =Languages!A207 -> Hierbij verklaart ondergetekende dat de inrichting van Cobra conform opgave in dit inventarisatie document is uitgevoerd.
A5: =Languages!A206 -> Klant
A6: =Languages!A34 -> Contactpersoon
A8: =Languages!A210 -> Akkoord met de Cobra setup:
A9: =Languages!A211 -> Akkoord met de schaduwverwerking(en):
A11: =Languages!A209 -> Datum:
A13: =Languages!A208 -> Handtekening:

Sheet Languages
A1: Value based on users choice | B1: Order | C1: Dutch | D1: English
A2: =IF(Explanation!$P$2="Nederlands",Tabel3[[#This Row],[Dutch]],Tabel3[[#This Row],[English]]) -> Voorkeurstaal document: | B2: 1 | C2: Voorkeurstaal document: | D2: Preferred language:
A3: =IF(Explanation!$P$2="Nederlands",Tabel3[[#This Row],[Dutch]],Tabel3[[#This Row],[English]]) -> Payroll inventarisatie document | B3: 2 | C3: Payroll inventarisatie document | D3: Payroll discovery document
A4: =IF(Explanation!$P$2="Nederlands",Tabel3[[#This Row],[Dutch]],Tabel3[[#This Row],[English]]) -> De gegevens in dit Excel-document zullen worden gebruikt voor de inrichting van het HRM- en salarissysteem (Cobra) | B4: 3 | C4: De gegevens in dit Excel-document zullen worden gebruikt voor de inrichting van het HRM- en salarissysteem (Cobra) | D4: The data in this Excel document will be used for the setup of the HRM and Salary system (Cobra)
A5: =IF(Explanation!$P$2="Nederlands",Tabel3[[#This Row],[Dutch]],Tabel3[[#This Row],[English]]) -> Het is belangrijk dat alle tabbladen worden ingevuld. Als een veld niet van toepassing is, geef dat dan aan met NVT | B5: 4 | C5: Het is belangrijk dat alle tabbladen worden ingevuld. Als een veld niet van toepassing is, geef dat dan aan met NVT | D5: It is important that all tabs are completed and filled in. If a field is not applicable, please indicate with N/A
A6: =IF(Explanation!$P$2="Nederlands",Tabel3[[#This Row],[Dutch]],Tabel3[[#This Row],[English]]) -> Als het niet helemaal duidelijk is wat er moet worden ingevuld, neem dan contact op met uw contactpersoon binnen SDWorx | B6: 5 | C6: Als het niet helemaal duidelijk is wat er moet worden ingevuld, neem dan contact op met uw contactpersoon binnen SDWorx | D6: If it is not entirely clear what must be filled in, please contact your contactperson within SDWorx
A7: =IF(Explanation!$P$2="Nederlands",Tabel3[[#This Row],[Dutch]],Tabel3[[#This Row],[English]]) -> Onderaan elke pagina is een opmerkingen veld opgenomen voor aanvullende informatie en uitleg | B7: 6 | C7: Onderaan elke pagina is een opmerkingen veld opgenomen voor aanvullende informatie en uitleg | D7: A comment box is included at the bottom of each page for additional information and explanation
A8: =IF(Explanation!$P$2="Nederlands",Tabel3[[#This Row],[Dutch]],Tabel3[[#This Row],[English]]) -> Indien dit document niet volledig is ingevuld kunnen we helaas niet starten met de (payroll) inrichting | B8: 7 | C8: Indien dit document niet volledig is ingevuld kunnen we helaas niet starten met de (payroll) inrichting | D8: If this document is not completely filled in, we can unfortunately not start with the (payroll) setup
A9: =IF(Explanation!$P$2="Nederlands",Tabel3[[#This Row],[Dutch]],Tabel3[[#This Row],[English]]) -> omdat aanpassingen in een later stadium complex zijn om door te voeren en onnodige vertragingen veroorzaken | B9: 8 | C9: omdat aanpassingen in een later stadium complex zijn om door te voeren en onnodige vertragingen veroorzaken | D9: because adjustments at a later stage are complex to implement and cause unnecessary delays
A10: =IF(Explanation!$P$2="Nederlands",Tabel3[[#This Row],[Dutch]],Tabel3[[#This Row],[English]]) -> Opstart documenten | B10: 9 | C10: Opstart documenten | D10: Start-up documents
A11: =IF(Explanation!$P$2="Nederlands",Tabel3[[#This Row],[Dutch]],Tabel3[[#This Row],[English]]) -> Voor de juiste opstart van de payroll hebben wij ook de volgende documenten nodig: | B11: 10 | C11: Voor de juiste opstart van de payroll hebben wij ook de volgende documenten nodig: | D11: For the correct start-up of the payroll, we also need the following documents:
A12: =IF(Explanation!$P$2="Nederlands",Tabel3[[#This Row],[Dutch]],Tabel3[[#This Row],[English]]) -> Kopie beschikking WHK premie lopend jaar | B12: 11 | C12: Kopie beschikking WHK premie lopend jaar | D12: Copy decision WHK premium current year
A13: =IF(Explanation!$P$2="Nederlands",Tabel3[[#This Row],[Dutch]],Tabel3[[#This Row],[English]]) -> Kopie historisch overzicht vorig jaar | B13: 12 | C13: Kopie historisch overzicht vorig jaar | D13: Copy of historical overview last year
... A211: =IF(Explanation!$P$2="Nederlands",Tabel3[[#This Row],[Dutch]],Tabel3[[#This Row],[English]]) -> Akkoord met de schaduwverwerking(en): | B211: 210 | C211: Akkoord met de schaduwverwerking(en): | D211: Accord with the parallelrun(s):
A212: =IF(Explanation!$P$2="Nederlands",Tabel3[[#This Row],[Dutch]],Tabel3[[#This Row],[English]]) -> 0 | B212: 211
A213: =IF(Explanation!$P$2="Nederlands",Tabel3[[#This Row],[Dutch]],Tabel3[[#This Row],[English]]) -> 0 | B213: 212
A214: =IF(Explanation!$P$2="Nederlands",Tabel3[[#This Row],[Dutch]],Tabel3[[#This Row],[English]]) -> 0 | B214: 213
A215: =IF(Explanation!$P$2="Nederlands",Tabel3[[#This Row],[Dutch]],Tabel3[[#This Row],[English]]) -> 0 | B215: 214
A216: =IF(Explanation!$P$2="Nederlands",Tabel3[[#This Row],[Dutch]],Tabel3[[#This Row],[English]]) -> 0 | B216: 215
A217: =IF(Explanation!$P$2="Nederlands",Tabel3[[#This Row],[Dutch]],Tabel3[[#This Row],[English]]) -> 0 | B217: 216
A218: =IF(Explanation!$P$2="Nederlands",Tabel3[[#This Row],[Dutch]],Tabel3[[#This Row],[English]]) -> 0 | B218: 217
A219: =IF(Explanation!$P$2="Nederlands",Tabel3[[#This Row],[Dutch]],Tabel3[[#This Row],[English]]) -> 0 | B219: 218
A220: =IF(Explanation!$P$2="Nederlands",Tabel3[[#This Row],[Dutch]],Tabel3[[#This Row],[English]]) -> 0 | B220: 219
A221: =IF(Explanation!$P$2="Nederlands",Tabel3[[#This Row],[Dutch]],Tabel3[[#This Row],[English]]) -> 0 | B221: 220
A222: =IF(Explanation!$P$2="Nederlands",Tabel3[[#This Row],[Dutch]],Tabel3[[#This Row],[English]]) -> 0 | B222: 221
A223: =IF(Explanation!$P$2="Nederlands",Tabel3[[#This Row],[Dutch]],Tabel3[[#This Row],[English]]) -> 0 | B223: 222
... A241: =IF(Explanation!$P$2="Nederlands",Tabel3[[#This Row],[Dutch]],Tabel3[[#This Row],[English]]) -> 0 | B241: 240

Sheet Validation values
A1: Preferred language | B1: Dutch | C1: English | E1: 1 – Agrarisch bedrijf
A2: =IF(Explanation!$P$2="Nederlands",Tabel2[[#This Row],[Dutch]],Tabel2[[#This Row],[English]]) -> Nederlands | B2: Nederlands | C2: Nederlands | E2: 2 – Tabakverwerkende industrie
A3: =IF(Explanation!$P$2="Nederlands",Tabel2[[#This Row],[Dutch]],Tabel2[[#This Row],[English]]) -> English | B3: English | C3: English | E3: 3 – Bouwbedrijf
E4: 4 – Baggerbedrijf
A5: Yes/No | B5: Dutch | C5: English | E5: 5 – Hout en emballage- industrie
A6: =IF(Explanation!$P$2="Nederlands",Tabel25[[#This Row],[Dutch]],Tabel25[[#This Row],[English]]) -> Ja | B6: Ja | C6: Yes | E6: 6 – Timmerindustrie
A7: =IF(Explanation!$P$2="Nederlands",Tabel25[[#This Row],[Dutch]],Tabel25[[#This Row],[English]]) -> Nee | B7: Nee | C7: No | E7: 7 – Meubel- en orgelbouw industrie
E8: 8 – Groothandel hout, zagerijen, schaverijen en houtbereidingsindustrie
A9: On-call employee | B9: Dutch | C9: English | E9: 9 – Grafische industrie
A10: =IF(Explanation!$P$2="Nederlands",Tabel256[[#This Row],[Dutch]],Tabel256[[#This Row],[English]]) -> Ja, met verplichting te komen | B10: Ja, met verplichting te komen | C10: Yes, obliged to come | E10: 10 – Metaal industrie
A11: =IF(Explanation!$P$2="Nederlands",Tabel256[[#This Row],[Dutch]],Tabel256[[#This Row],[English]]) -> Ja, zonder verplichting te komen | B11: Ja, zonder verplichting te komen | C11: Yes, not obliged to come | E11: 11 – Elektronische industrie
A12: =IF(Explanation!$P$2="Nederlands",Tabel256[[#This Row],[Dutch]],Tabel256[[#This Row],[English]]) -> Ja, beide | B12: Ja, beide | C12: Yes, both | E12: 12 – Metaal – en technische bedrijfstakken
A13: =IF(Explanation!$P$2="Nederlands",Tabel256[[#This Row],[Dutch]],Tabel256[[#This Row],[English]]) -> Nee | B13: Nee | C13: No | E13: 13 – Bakkerijen
E14: 14 – Suikerverwerkende industrie
A15: Proration calculation based on | B15: Dutch | C15: English | E15: 15 – Slagersbedrijven
A16: =IF(Explanation!$P$2="Nederlands",Tabel2567[[#This Row],[Dutch]],Tabel2567[[#This Row],[English]]) -> Rooster dagen | B16: Rooster dagen | C16: Work schedule days | E16: 16 – Slagers overig
A17: =IF(Explanation!$P$2="Nederlands",Tabel2567[[#This Row],[Dutch]],Tabel2567[[#This Row],[English]]) -> Gemiddelde dagen | B17: Gemiddelde dagen | C17: Average days | E17: 17 – Detailhandel en ambachten
A18: =IF(Explanation!$P$2="Nederlands",Tabel2567[[#This Row],[Dutch]],Tabel2567[[#This Row],[English]]) -> Kalender dagen | B18: Kalender dagen | C18: Calender days | E18: 18 – Reiniging
E19: 19 – Grootwinkelbedrijf
A20: Wage period | B20: Dutch | C20: English | E20: 20 – Havenbedrijven
A21: =IF(Explanation!$P$2="Nederlands",Tabel25678[[#This Row],[Dutch]],Tabel25678[[#This Row],[English]]) -> Week | B21: Week | C21: Week | E21: 21 – Havenclassificeerders
A22: =IF(Explanation!$P$2="Nederlands",Tabel25678[[#This Row],[Dutch]],Tabel25678[[#This Row],[English]]) -> 4 weken | B22: 4 weken | C22: 4 weeks | E22: 22 – Binnenscheepvaart
A23: =IF(Explanation!$P$2="Nederlands",Tabel25678[[#This Row],[Dutch]],Tabel25678[[#This Row],[English]]) -> Maand | B23: Maand | C23: Month | E23: 23 – Visserij
E24: 24 – Koopvaardij
A25: Preferred language 2 | B25: Dutch | C25: English | E25: 25 – Vervoer KLM
A26: =IF(Explanation!$P$2="Nederlands",Tabel29[[#This Row],[Dutch]],Tabel29[[#This Row],[English]]) -> Nederlands | B26: Nederlands | C26: Dutch | E26: 26 – Vervoer NS
A27: =IF(Explanation!$P$2="Nederlands",Tabel29[[#This Row],[Dutch]],Tabel29[[#This Row],[English]]) -> Engels | B27: Engels | C27: English | E27: 27 – Vervoer posterijen
E28: 28 – Taxivervoer
A29: Payslip visible for employee | B29: Dutch | C29: English | E29: 29 – Openbaar vervoer
A30: =IF(Explanation!$P$2="Nederlands",Tabel2910[[#This Row],[Dutch]],Tabel2910[[#This Row],[English]]) -> Op de betaaldatum | B30: Op de betaaldatum | C30: On credit date | E30: 30 – Besloten busvervoer
A31: =IF(Explanation!$P$2="Nederlands",Tabel2910[[#This Row],[Dutch]],Tabel2910[[#This Row],[English]]) -> # dagen na de betaaldatum | B31: # dagen na de betaaldatum | C31: # days after credit date | E31: 31 – Overig personenvervoer te land en in de lucht
E32: 32 – Overig goederenvervoer te land en in de lucht
A33: Classification employer | B33: Dutch | C33: English | E33: 33 – Horeca algemeen
A34: =IF(Explanation!$P$2="Nederlands",Tabel291011[[#This Row],[Dutch]],Tabel291011[[#This Row],[English]]) -> Klein | B34: Klein | C34: Small | E34: 34 – Horeca catering
A35: =IF(Explanation!$P$2="Nederlands",Tabel291011[[#This Row],[Dutch]],Tabel291011[[#This Row],[English]]) -> Middel | B35: Middel | C35: Medium | E35: 35 – Gezondheid, geestelijke en maatschappelijke belangen
A36: =IF(Explanation!$P$2="Nederlands",Tabel291011[[#This Row],[Dutch]],Tabel291011[[#This Row],[English]]) -> Groot | B36: Groot | C36: Large | E36: 38 – Banken
E37: 39 – Verzekeringswezen en ziekenfondsen
A38: Own risk policy | B38: Dutch | C38: English | E38: 40 – Uitgeverij
A39: =IF(Explanation!$P$2="Nederlands",Tabel29101112[[#This Row],[Dutch]],Tabel29101112[[#This Row],[English]]) -> Nee | B39: Nee | C39: No | E39: 41 – Groothandel I
A40: =IF(Explanation!$P$2="Nederlands",Tabel29101112[[#This Row],[Dutch]],Tabel29101112[[#This Row],[English]]) -> WGA | B40: WGA | C40: WGA | E40: 42 – Groothandel II
...
